<<< PROJECT PART I
<<< -- process set (n=3) with 1 CPU-bound process
<<< -- seed=32; lambda=0.001000; bound=1024
CPU-bound process A0: arrival time 319ms; 25 CPU bursts
I/O-bound process A1: arrival time 506ms; 5 CPU bursts
I/O-bound process A2: arrival time 821ms; 15 CPU bursts

<<< PROJECT PART II
<<< -- t_cs=4ms; alpha=0.75; t_slice=256ms
time 0ms: Simulator started for FCFS [Q empty]
time 319ms: Process A0 arrived; added to ready queue [Q A0]
time 321ms: Process A0 started using the CPU for 1448ms burst [Q empty]
time 506ms: Process A1 arrived; added to ready queue [Q A1]
time 821ms: Process A2 arrived; added to ready queue [Q A1 A2]
time 1769ms: Process A0 completed a CPU burst; 24 bursts to go [Q A1 A2]
time 1769ms: Process A0 switching out of CPU; blocking on I/O until time 2379ms [Q A1 A2]
time 1773ms: Process A1 started using the CPU for 971ms burst [Q A2]
time 2379ms: Process A0 completed I/O; added to ready queue [Q A2 A0]
time 2744ms: Process A1 completed a CPU burst; 4 bursts to go [Q A2 A0]
time 2744ms: Process A1 switching out of CPU; blocking on I/O until time 3178ms [Q A2 A0]
time 2748ms: Process A2 started using the CPU for 408ms burst [Q A0]
time 3156ms: Process A2 completed a CPU burst; 14 bursts to go [Q A0]
time 3156ms: Process A2 switching out of CPU; blocking on I/O until time 8670ms [Q A0]
time 3160ms: Process A0 started using the CPU for 316ms burst [Q empty]
time 3178ms: Process A1 completed I/O; added to ready queue [Q A1]
time 3476ms: Process A0 completed a CPU burst; 23 bursts to go [Q A1]
time 3476ms: Process A0 switching out of CPU; blocking on I/O until time 3952ms [Q A1]
time 3480ms: Process A1 started using the CPU for 129ms burst [Q empty]
time 3609ms: Process A1 completed a CPU burst; 3 bursts to go [Q empty]
time 3609ms: Process A1 switching out of CPU; blocking on I/O until time 4875ms [Q empty]
time 3952ms: Process A0 completed I/O; added to ready queue [Q A0]
time 3954ms: Process A0 started using the CPU for 3556ms burst [Q empty]
time 4875ms: Process A1 completed I/O; added to ready queue [Q A1]
time 7510ms: Process A0 completed a CPU burst; 22 bursts to go [Q A1]
time 7510ms: Process A0 switching out of CPU; blocking on I/O until time 8476ms [Q A1]
time 7514ms: Process A1 started using the CPU for 188ms burst [Q empty]
time 7702ms: Process A1 completed a CPU burst; 2 bursts to go [Q empty]
time 7702ms: Process A1 switching out of CPU; blocking on I/O until time 9200ms [Q empty]
time 8476ms: Process A0 completed I/O; added to ready queue [Q A0]
time 8478ms: Process A0 started using the CPU for 2516ms burst [Q empty]
time 8670ms: Process A2 completed I/O; added to ready queue [Q A2]
time 9200ms: Process A1 completed I/O; added to ready queue [Q A2 A1]
time 12891ms: Process A1 terminated [Q empty]
time 52148ms: Process A0 terminated [Q empty]
time 66002ms: Process A2 terminated [Q empty]
time 66004ms: Simulator ended for FCFS [Q empty]

time 0ms: Simulator started for SJF [Q empty]
time 319ms: Process A0 (tau 1000ms) arrived; added to ready queue [Q A0]
time 321ms: Process A0 (tau 1000ms) started using the CPU for 1448ms burst [Q empty]
time 506ms: Process A1 (tau 1000ms) arrived; added to ready queue [Q A1]
time 821ms: Process A2 (tau 1000ms) arrived; added to ready queue [Q A1 A2]
time 1769ms: Process A0 (tau 1000ms) completed a CPU burst; 24 bursts to go [Q A1 A2]
time 1769ms: Recalculated tau for process A0: old tau 1000ms ==> new tau 1000ms [Q A1 A2]
time 1769ms: Process A0 (tau 1000ms) switching out of CPU; blocking on I/O until time 2379ms [Q A1 A2]
time 1773ms: Process A1 (tau 1000ms) started using the CPU for 971ms burst [Q A2]
time 2379ms: Process A0 (tau 1336ms) completed I/O; added to ready queue [Q A2 A0]
time 2744ms: Process A1 (tau 1000ms) completed a CPU burst; 4 bursts to go [Q A2 A0]
time 2744ms: Recalculated tau for process A1: old tau 1000ms ==> new tau 1000ms [Q A2 A0]
time 2744ms: Process A1 (tau 1000ms) switching out of CPU; blocking on I/O until time 3178ms [Q A2 A0]
time 2748ms: Process A2 (tau 1000ms) started using the CPU for 408ms burst [Q A0]
time 3156ms: Process A2 (tau 1000ms) completed a CPU burst; 14 bursts to go [Q A0]
time 3156ms: Recalculated tau for process A2: old tau 1000ms ==> new tau 1000ms [Q A0]
time 3156ms: Process A2 (tau 1000ms) switching out of CPU; blocking on I/O until time 8670ms [Q A0]
time 3160ms: Process A0 (tau 1336ms) started using the CPU for 316ms burst [Q empty]
time 3178ms: Process A1 (tau 978ms) completed I/O; added to ready queue [Q A1]
time 3476ms: Process A0 (tau 1336ms) completed a CPU burst; 23 bursts to go [Q A1]
time 3476ms: Recalculated tau for process A0: old tau 1336ms ==> new tau 1336ms [Q A1]
time 3476ms: Process A0 (tau 1336ms) switching out of CPU; blocking on I/O until time 3952ms [Q A1]
time 3480ms: Process A1 (tau 978ms) started using the CPU for 129ms burst [Q empty]
time 3609ms: Process A1 (tau 978ms) completed a CPU burst; 3 bursts to go [Q empty]
time 3609ms: Recalculated tau for process A1: old tau 978ms ==> new tau 978ms [Q empty]
time 3609ms: Process A1 (tau 978ms) switching out of CPU; blocking on I/O until time 4875ms [Q empty]
time 3952ms: Process A0 (tau 571ms) completed I/O; added to ready queue [Q A0]
time 3954ms: Process A0 (tau 571ms) started using the CPU for 3556ms burst [Q empty]
time 4875ms: Process A1 (tau 341ms) completed I/O; added to ready queue [Q A1]
time 7510ms: Process A0 (tau 571ms) completed a CPU burst; 22 bursts to go [Q A1]
time 7510ms: Recalculated tau for process A0: old tau 571ms ==> new tau 571ms [Q A1]
time 7510ms: Process A0 (tau 571ms) switching out of CPU; blocking on I/O until time 8476ms [Q A1]
time 7514ms: Process A1 (tau 341ms) started using the CPU for 188ms burst [Q empty]
time 7702ms: Process A1 (tau 341ms) completed a CPU burst; 2 bursts to go [Q empty]
time 7702ms: Recalculated tau for process A1: old tau 341ms ==> new tau 341ms [Q empty]
time 7702ms: Process A1 (tau 341ms) switching out of CPU; blocking on I/O until time 9200ms [Q empty]
time 8476ms: Process A0 (tau 2809ms) completed I/O; added to ready queue [Q A0]
time 8478ms: Process A0 (tau 2809ms) started using the CPU for 2516ms burst [Q empty]
time 8670ms: Process A2 (tau 556ms) completed I/O; added to ready queue [Q A2]
time 9200ms: Process A1 (tau 226ms) completed I/O; added to ready queue [Q A1 A2]
time 12705ms: Process A1 terminated [Q empty]
time 52148ms: Process A0 terminated [Q empty]
time 66002ms: Process A2 terminated [Q empty]
time 66004ms: Simulator ended for SJF [Q empty]
